<?xml version="1.0"?>
<robot name="nda_robot">
  <link name="base_link"/>
 
  <link name="base_footprint"/>
  <joint name="base_link_to_base_footprint" type="fixed">
    <parent link="base_footprint"/>
    <child link="base_link"/>
    <origin xyz="0 0 0.15"/>
  </joint>

  <link name="housing_link">
    <visual>
      <geometry>
        <box size="1.0 0.4 1.0"/>
      </geometry>
    </visual>
    <collision>
      <geometry>
        <box size="1.0 0.4 1.0"/>
      </geometry>
    </collision>
    <inertial>
	<mass value="20.0"/>
	<inertia ixx="1.9333" ixy="0" ixz="0"
                 iyy="3.3333" iyz="0" izz="1.9333"/>
    </inertial>
  </link>
<!--
  <gazebo reference="housing_link">
    <selfCollide>false</selfCollide>
    <mu1 value="0" />
    <mu2 value="0" />
  </gazebo>
  -->
  <joint name="base_link_to_housing_link" type="fixed">
    <parent link="base_link"/>
    <child link="housing_link"/>
    <origin xyz="0.25 0 0.5"/>
  </joint>

  <link name="right_wheel_link">
    <visual>
      <geometry>
        <cylinder length="0.05" radius="0.15"/>
      </geometry>
    </visual>
    <collision>
      <geometry>
        <cylinder length="0.05" radius="0.15"/>
      </geometry>
    </collision>
    <inertial>
      <mass value="1.0"/>
      <inertia ixx="0.00583" ixy="0" ixz="0"
               iyy="0.00583" iyz="0" izz="0.01125"/>
    </inertial>
  </link>
  <gazebo reference="right_wheel_link">
    <selfCollide>false</selfCollide>
    <mu1 value="0.8" />
    <mu2 value="0.8" />
  </gazebo>
      
  <joint name="base_link_to_right_wheel_link" type="continuous">
    <parent link="base_link"/>
    <child link="right_wheel_link"/>
    <origin xyz="0 -0.24 0" rpy="1.57 0 0"/>
    <axis xyz="0 0 -1"/>
  </joint>
    
  <transmission name="right_wheel_trans">
    <type>transmission_interface/SimpleTransmission</type>
    <joint name="base_link_to_right_wheel_link">
      <hardwareInterface>VelocityJointInterface</hardwareInterface>
    </joint>
    <actuator name="right_wheel_motor">
      <hardwareInterface>VelocityJointInterface</hardwareInterface>
      <mechanicalReduction>30</mechanicalReduction>
    </actuator>
  </transmission>

  <link name="left_wheel_link">
    <visual>
      <geometry>
        <cylinder length="0.05" radius="0.15"/>
      </geometry>
    </visual>
  <collision>
    <geometry>
      <cylinder length="0.05" radius="0.15"/>
    </geometry>
  </collision>
  <inertial>
    <mass value="1.0"/>
    <inertia ixx="0.00583" ixy="0" ixz="0"
             iyy="0.00583" iyz="0" izz="0.01125"/>
    </inertial>
  </link>
  <gazebo reference="left_wheel_link">
    <selfCollide>false</selfCollide>
    <mu1 value="0.8" />
    <mu2 value="0.8" />
  </gazebo>
  
  <joint name="base_link_to_left_wheel_link" type="continuous">
    <parent link="base_link"/>
    <child link="left_wheel_link"/>
    <origin xyz="0 0.24 0" rpy="1.57 0 0"/>
    <axis xyz="0 0 1"/>
  </joint>
  
  <transmission name="left_wheel_trans">
    <type>transmission_interface/SimpleTransmission</type>
    <joint name="base_link_to_left_wheel_link">
      <hardwareInterface>VelocityJointInterface</hardwareInterface>
    </joint>
    <actuator name="left_wheel_motor">
      <hardwareInterface>VelocityJointInterface</hardwareInterface>
      <mechanicalReduction>30</mechanicalReduction>
    </actuator>
  </transmission>

  <link name="center_wheel_link">
    <visual>
      <geometry>
        <cylinder length="0.05" radius="0.075"/>
      </geometry>
    </visual>
    <collision>
      <geometry>
        <cylinder length="0.05" radius="0.075"/>
      </geometry>
    </collision>
    <inertial>
      <mass value="1.0"/>
      <inertia ixx="0.00583" ixy="0" ixz="0"
               iyy="0.00583" iyz="0" izz="0.01125"/>
    </inertial>
  </link>
  <gazebo reference="center_wheel_link">
    <selfCollide>false</selfCollide>
    <mu1 value="0.05" />
    <mu2 value="0.05" />
  </gazebo>
  
  <joint name="base_link_to_center_wheel_link" type="fixed">
    <parent link="base_link"/>
    <child link="center_wheel_link"/>
    <origin xyz="0.5 0 -0.075" rpy="-1.57 0 0"/>
  </joint>

  <link name="left_lrf_link"/>
  <joint name="base_link_to_left_lrf_link" type="fixed">
    <parent link="base_link"/>
    <child link="left_lrf_link"/>
    <origin xyz="0 0.2305 0.2141" rpy="0 0 1.57"/>
  </joint>
  <gazebo reference="left_lrf_link">
    <sensor type="ray" name="left_lrf_sensor">
      <pose>0 0 0 0 0 0</pose>
      <visualize>false</visualize>
      <update_rate>40</update_rate>
      <ray>
        <scan>
	  <horizontal>
	    <samples>720</samples>
	     <resolution>1</resolution>
             <min_angle>-1.57</min_angle>
	     <max_angle>1.57</max_angle>
	   </horizontal>
	 </scan>
       <range>
         <min>0.02</min>
	 <max>30.0</max>
	 <resolution>0.001</resolution>
       </range>
       <noise>
         <type>gaussian</type>
	 <mean>0.0</mean>
	 <stddev>0.03</stddev>
       </noise>
     </ray>
     <plugin name="gazebo_ros_left_lrf_controller" filename="libgazebo_ros_laser.so">
       <topicName>left/scan</topicName>
       <frameName>left_lrf_link</frameName>
     </plugin>
   </sensor>
 </gazebo>
 
 <link name="right_lrf_link"/>
 <joint name="base_link_to_right_lrf_link" type="fixed">
   <parent link="base_link"/>
   <child link="right_lrf_link"/>
   <origin xyz="0 -0.2305 0.2141" rpy="0 0 -1.57"/>
 </joint>
 <gazebo reference="right_lrf_link">
   <sensor type="ray" name="right_lrf_sensor">
     <pose>0 0 0 0 0 0</pose>
     <visualize>false</visualize>
     <update_rate>40</update_rate>
     <ray>
       <scan>
         <horizontal>
	   <samples>720</samples>
	   <resolution>1</resolution>
	   <min_angle>-1.57</min_angle>
	   <max_angle>1.57</max_angle>
	 </horizontal>
       </scan>
       <range>
         <min>0.02</min>
	 <max>30.0</max>
	 <resolution>0.001</resolution>
       </range>
       <noise>
         <type>gaussian</type>
	 <mean>0.0</mean>
	 <stddev>0.03</stddev>
       </noise>
     </ray>
     <plugin name="gazebo_ros_right_lrf_controller" filename="libgazebo_ros_laser.so">
       <topicName>right/scan</topicName>
       <frameName>right_lrf_link</frameName>
     </plugin>
   </sensor>
 </gazebo>
 
 <link name="lrf_link"/>
 <joint name="base_link_to_lrf_link" type="fixed">
   <parent link="base_link"/>
   <child link="lrf_link"/>
   <origin xyz="0 0 0.2141"/>
 </joint>
 
 <link name="imu_link"/>
 <joint name="base_link_to_imu_link" type="fixed">
   <parent link="base_link"/>
   <child link="imu_link"/>
   <origin xyz="0 0 0.1"/>
 </joint>
 
 <gazebo>
   <plugin name="gazebo_ros_control" filename="libgazebo_ros_control.so">
   </plugin>
 </gazebo>

</robot>			    